Workbook

Sheet 0. 시트 사용 안내
B3: {프로젝트}_총괄시트 | D3: URL: | E3: 12yQ9cf_DJyvkVFeRTAHQ8g6rbDJHs8wwXmYrqcQ7wNQ
B4: 시트 이름 | C4: 용도 | D4: 사용 가이드 | E4: 상세 열 설명
B5: 1. WBS | C5: 프로젝트 진행 관리 시트 | D5: 각 행은 하나의 작업으로, 수행 가능한 단위로 작성하며 데이터 / 고객사 / 운영 관리 항목 별로 구분하여 사용 가능. 작업 진행에 따라 현황 및 상세 내용을 업데이트 하며 관리. | E5: 단계: 작업이 수행될 진행 단계를 구분. 내용: 요약 혹은 대표되는 작업을 입력. 진행 현황: 일정 변경되면 연기, 내용이 크게 변경되면 변경을 사용. 상세 내용: 작업에 대한 상세 내용을 작성하고, 추가·변경된 내용도 업데이트 하며 관리. 다른 색상으로 표기하면 구분 용이.
B6: 2. 도서 정보 | C6: 도서 정보 및 자동화 연동 시트 | D6: 도서 기본 정보를 입력하고, 인프라넷과 연동하여 원천데이터를 분석한 내용이 입력됨.(희망) | E6: A열~G열: 도서 정보 H열: 문학, 금융 등 도서 분야 분류 I열~L열: 정제 범위 정보 M열~N열: fitz 정보 O열~S열: 라벨 별 개수(백분위 기준 상위 셀서식 조건 존재) T열~V열: 텍스트 분석 정보 W열: 분석 정보 기반 난이도 분류(프로젝트 별 활용)
B7: 3. 도서별 작업 현황 | C7: 도서별 작업 진행 관리 시트 | D7: ID 기준으로 도서에 관한 정보 및 진행이 업데이트 됨. 작업자 관리 시트에서 가져오는 열이 많기 때문에 연동된 열은 작업자 관리 시트에서 수정 권장. | E7: A열~E열: 도서 정보.(1.도서정보 시트 연동) F열~K열: bbox&ocr 작업 진행 정보.(bbox&ocr 작업자 관리 시트 연동) L열~O열: LaTeX 작업 진행 정보.(latex 작업자 관리 시트 연동) P열~: 최종 검수 및 파싱. 필요한 추가적인 열 생성 가능.
B8: 4. 작업자 관리 | C8: 작업자 총괄 시트 | D8: 작업자 관리 시트와 별도로 작업자의 평가/보수까지 관리하기 위한 시트. 작업 별 표가 나뉘어져 있으며, 보수에 따라 입력하여 사용. | E8: F열~G열: 에러 코드 활용 열. 오류 발생 페이지 수 입력. (임시) I열~J열: bbox&ocr 작업자 관리 시트 연동 V열: latex 작업자 관리 시트 연동
B9: 5. 납품 전 체크리스트 | C9: 데이터 품질 관리 시트 | D9: 파싱된 데이터 검수 및 관리. 품질 보완에 활용. 현재는 기본적인 항목만 작성된 상태로, 프로젝트 별 검수 항목을 자유롭게 추가하여 사용. | E9: A열~D열: 도서 정보.(1.도서정보 시트 연동) F열~ : 파싱 후 검수 항목들. 공용 검수툴 기반 반영 필요.
B10: *PoC | C10: 착수 전 PoC 활용 시트 | D10: 작업 별 활용 가능하도록 2개 세트로 생성. 진행해야 할 작업에 따라 작업 내용 수정하여 사용. | E10: 단가: 페이지와 시간으로 페이지 당 단가를 계산.(함수 존재) 서식열: 왼쪽 단가 값에 대한 평균(함수 존재)
B11: *WER 로그
B12: *드롭다운 클래스
B16: {프로젝트}_작업자 관리 시트 | D16: URL : | E16: 135Pv3GNyfbE2Q4wIPGQTLZCsUJKkhrN1_ha6dyN-n_0
B17: 시트 이름 | C17: 용도 | D17: 사용 가이드 | E17: 상세 열 설명
B18: 1. 확인 사항 | C18: 작업자 확인사항 체크 시트 | D18: 작업자의 기본 정보 입력 후, 작업 전 확인이 필요한 사항에 대해 작업자가 확인하고 직접 체크하는 시트. | E18: 초록색 서식 열: 작업 전 필수로 확인해야 하는 항목. 분홍색 서식 열: 프로젝트 별 활용 가능한 항목.
B19: 2. 작업 일정 | C19: 작업자 작업 일정 시트 | D19: 작업 전 작업자가 작업 가능한 시간대 및 시간을 입력. 작업 일정 관리와 분배사항에 참고할 수 있고, 작업 기간에 따라 추가 생성 후 관리. | E19: 가능한 총 근무시간: 일주일 합계.(함수 존재)
B20: 3. 작업 현황 | C20: 작업자 대시보드 시트 | D20: 관리용 시트에 입력되어 있는 내용을 기반으로 작업자 별 작업 수량 현황과 현재 작업 도서 현황을 확인 및 관리 가능. 이름과 아이디만 입력하면 대부분 자동 입력되는 열로, 작업 분배나 현황 파악 시 활용. | E20: BBOX(OCR) 분배 페이지: 작업자 이름이 해당 작업자인 도서의 페이지 수 합계. BBOX(OCR) 완료 페이지: 작업 상태가 완료 혹은 반려 완료는 도서의 페이지 수 합계. 소요 기간: 분배 날짜로부터 오늘까지의 일 수 분배 필요: 분배 필요 여부를 빠르게 확인하기 위한 열. "진행중" 혹은 "반려" 상태가 없을 때, 분배 필요 표시.
B21: 4. 관리용(bbox&ocr) | C21: 도서 별 작업 관리 시트 | D21: bbox와 ocr 작업자 전용 관리 시트로, latex 작업 전까지 작업 단계를 총괄하여 관리. 총괄시트과 연동되어 있는 내용이 많아, 열을 추가할 시 O열 이후 추가를 권장. | E21: A열~E열: 도서 정보.(총괄 시트 연동) 저자/출판사 열은 분배 시 활용. F열: 분배 날짜. 분배 시 직접 입력. G열~O열: 총괄 시트에 반영 되는 항목.
B22: 4. 관리용(latex) | C22: 분배 별 작업 관리 시트 | D22: 2개의 표 존재, A열~G열의 표는 분배 관리 표로 분배 별 수량과 도서 작업 상태를 기록하고 확인. I열부터 시작하는 표는 작업자 별 관리 표로, 각 행이 하나의 작업자로 제출 폴더 별로 작업 상태 및 검수를 관리. | E22: F열~H열: 총괄 시트에 반영 되는 항목. J열~: 분배 관리 표 기준으로 업데이트 되는 항목.(자동 업데이트 희망)

Sheet 1. 프로젝트 대시보드
A1: {프로젝트} 대시보드
M2: 도서 단계별 현황
A3: 총 도서 수 | C3: 총 페이지 | E3: 전체 진척도 | G3: 완료 도서 | I3: 진행 도서 | M3: 구분 | N3: 총 | O3: 분배 전 | P3: BBOX | Q3: OCR | R3: 수식표 | S3: 완료
A4: =N4 -> 107 | C4: =N5 -> 0 | E4: =IFERROR((SUM('3. 도서별 작업 현황'!$G$2:$G$500)+SUM('3. 도서별 작업 현황'!$L$2:$L$500)+SUM('3. 도서별 작업 현황'!$Q$2:$Q$500))/($N$5*3),0) -> 0 | G4: =S4 -> 0 | I4: =MAX(0,N4-O4-S4) -> 1 | M4: 권 | N4: =COUNTIF('3. 도서별 작업 현황'!A2:A999,"<>") -> 107 | O4: =COUNTIFS('3. 도서별 작업 현황'!A2:A999,"<>",'3. 도서별 작업 현황'!F2:F999,"",'3. 도서별 작업 현황'!K2:K999,"",'3. 도서별 작업 현황'!P2:P999,"") -> 106
M5: 페이지 | N5: =SUMIF('3. 도서별 작업 현황'!C2:C999,">0") -> 0 | O5: =SUMIFS('3. 도서별 작업 현황'!C2:C999,'3. 도서별 작업 현황'!F2:F999,"",'3. 도서별 작업 현황'!K2:K999,"",'3. 도서별 작업 현황'!P2:P999,"") -> #NAME?
A7: 단계 | B7: 분배 페이지 | C7: 완료 페이지 | D7: 완료율 | F7: 기준 • 단계 현황은 3. 도서별 작업 현황 시트 기준 • 전체 진척도 = (BBOX 완료 + OCR 완료 + 수식표 완료) ÷ (총 페이지 × 3) • 완료 도서는 수식표 완료 페이지가 입력된 도서 기준
A8: BBOX | D8: =IFERROR(C8/$N$5,0) -> 0
A9: OCR | D9: =IFERROR(C9/$N$5,0) -> 0
A10: 수식표 | D10: =IFERROR(C10/$N$5,0) -> 0
I11: =TEXT(I12,"m월") -> 3월 | J11: =IF(TEXT(J12,"yyyymm")=TEXT(I12,"yyyymm"),"",TEXT(J12,"m월")) | K11: =IF(TEXT(K12,"yyyymm")=TEXT(J12,"yyyymm"),"",TEXT(K12,"m월")) | L11: =IF(TEXT(L12,"yyyymm")=TEXT(K12,"yyyymm"),"",TEXT(L12,"m월")) | M11: =IF(TEXT(M12,"yyyymm")=TEXT(L12,"yyyymm"),"",TEXT(M12,"m월")) | N11: =IF(TEXT(N12,"yyyymm")=TEXT(M12,"yyyymm"),"",TEXT(N12,"m월")) | O11: =IF(TEXT(O12,"yyyymm")=TEXT(N12,"yyyymm"),"",TEXT(O12,"m월")) | P11: =IF(TEXT(P12,"yyyymm")=TEXT(O12,"yyyymm"),"",TEXT(P12,"m월")) | Q11: =IF(TEXT(Q12,"yyyymm")=TEXT(P12,"yyyymm"),"",TEXT(Q12,"m월")) | ... GZ11: =IF(TEXT(GZ12,"yyyymm")=TEXT(GY12,"yyyymm"),"",TEXT(GZ12,"m월"))
A12: TASK | B12: 담당자 | C12: 시작일 | D12: 종료일 | E12: 단계 | F12: 산출물 | G12: 세부내용 | I12: =IF(COUNT($C$13:$C$37)=0,TODAY()-WEEKDAY(TODAY(),2)+1,MIN($C$13:$C$37)-WEEKDAY(MIN($C$13:$C$37),2)+1) -> 46090 | J12: =I12+1 -> 46091 | K12: =J12+1 -> 46092 | L12: =K12+1 -> 46093 | M12: =L12+1 -> 46094 | N12: =M12+1 -> 46095 | O12: =N12+1 -> 46096 | P12: =O12+1 -> 46097 | Q12: =P12+1 -> 46098 | ... GZ12: =GY12+1 -> 46289
A13: 프로젝트 설계 | B13: PM | C13: 2026.01.05 | D13: 46080 | E13: 완료
A14: BBOX 작업 | B14: DA1 | C14: 46090 | D14: 46108 | E14: 진행 중
A15: 기준안 협의 | B15: PM | C15: 46090 | D15: 46093 | E15: 완료
C16: 46090 | D16: 46108 | E16: 보류
C17: 46090 | D17: 46108 | E17: 시작 전

Sheet 2. 도서 정보
P1: * BBOX 수 | Z1: * 포함 비율 | AD1: * 개
A2: ID | B2: 도서명 | C2: ISBN | D2: 저자 | E2: 출판사 | F2: 출판일 | G2: 포맷 | H2: 분류1 | I2: 분류2 | J2: 분류3 | K2: 전체 페이지 | L2: 시작 페이지 | M2: 끝 페이지 | N2: 작업 페이지 | O2: 추출 방식 | P2: 텍스트 | Q2: 타이틀 | R2: 캡션 | S2: 이미지 | T2: 수식 | U2: 표 | V2: 차트 | W2: 각주 | X2: 아이템 | Y2: 빈 텍스트 박스 | Z2: 띄어쓰기 | AA2: 영어 | AB2: 기타 외국어 | AC2: 특수문자 | AD2: 어절 | AE2: 박스(<2) | AF2: 다단 의심 | AG2: 다단 여부 | AH2: 난이도 | AI2: 특이사항
A3: SS0001 | B3: 도서1 | G3: pdf | K3: 55 | L3: 2 | M3: 53 | N3: =IF((M3-L3)>0, M3-L3+1, 0) -> 52 | O3: fitz | P3: 288 | AG3: 다단 도서 | AH3: A
A4: SS0002 | B4: 도서2 | G4: epub | K4: 44 | L4: 5 | M4: 40 | N4: =IF((M4-L4)>0, M4-L4+1, 0) -> 36 | O4: gemini | P4: 323 | AG4: 일부 존재 | AH4: C
A5: SS0003 | B5: 도서3 | K5: 100 | L5: 8 | M5: 91 | N5: =IF((M5-L5)>0, M5-L5+1, 0) -> 84 | O5: GPT
A6: SS0004 | B6: 도서4 | K6: 2000 | L6: 3 | M6: 1987 | N6: =IF((M6-L6)>0, M6-L6+1, 0) -> 1985 | O6: 내부 모델
A7: SS0005 | K7: 10 | L7: 1 | M7: 10 | N7: =IF((M7-L7)>0, M7-L7+1, 0) -> 10
A8: SS0006 | K8: 10 | L8: 1 | M8: 10 | N8: =IF((M8-L8)>0, M8-L8+1, 0) -> 10 | P8: 320
A9: SS0007 | K9: 15 | L9: 3 | M9: 15 | N9: =IF((M9-L9)>0, M9-L9+1, 0) -> 13 | P9: 476
A10: SS0008 | N10: =IF((M10-L10)>0, M10-L10+1, 0) -> 0 | P10: 354
A11: SS0009 | N11: =IF((M11-L11)>0, M11-L11+1, 0) -> 0 | P11: 248
A12: SS0010 | N12: =IF((M12-L12)>0, M12-L12+1, 0) -> 0 | P12: 640
A13: SS0011 | N13: =IF((M13-L13)>0, M13-L13+1, 0) -> 0 | P13: 248
A14: SS0012 | N14: =IF((M14-L14)>0, M14-L14+1, 0) -> 0 | P14: 212
A15: SS0013 | N15: =IF((M15-L15)>0, M15-L15+1, 0) -> 0 | P15: 360
A16: SS0014 | N16: =IF((M16-L16)>0, M16-L16+1, 0) -> 0 | P16: 299
A17: SS0015 | N17: =IF((M17-L17)>0, M17-L17+1, 0) -> 0 | P17: 288
A18: SS0016 | N18: =IF((M18-L18)>0, M18-L18+1, 0) -> 0 | P18: 532
A19: SS0017 | N19: =IF((M19-L19)>0, M19-L19+1, 0) -> 0 | P19: 328
A20: SS0018 | N20: =IF((M20-L20)>0, M20-L20+1, 0) -> 0 | P20: 391
A21: SS0019 | N21: =IF((M21-L21)>0, M21-L21+1, 0) -> 0 | P21: 288
... A111: SS0230 | N111: =IF((M111-L111)>0, M111-L111+1, 0) -> 0 | P111: 1753
A112: open_data_2st | N112: =IF((M112-L112)>0, M112-L112+1, 0) -> 0 | P112: 2406 | Q112: 55 | R112: 71 | S112: 99 | T112: 17 | U112: 160 | V112: 39 | W112: 124 | X112: 33 | Y112: 2450 | Z112: 0.2038 | AA112: 0.0061 | AB112: 0.0007 | AC112: 0.2260 | AD112: 2707 | AE112: 14 | AF112: 34

Sheet 2. 도서 정보의 사본
N1: * BBOX 수 | X1: * 포함 비율 | AB1: * 개
A2: ID | B2: 도서명 | C2: ISBN | D2: 저자 | E2: 출판사 | F2: 출판일 | G2: 포맷 | H2: 분류 | I2: 전체 페이지 | J2: 시작 페이지 | K2: 끝 페이지 | L2: 작업 페이지 | M2: 추출 방식 | N2: 텍스트 | O2: 타이틀 | P2: 캡션 | Q2: 이미지 | R2: 수식 | S2: 표 | T2: 차트 | U2: 각주 | V2: 아이템 | W2: 빈 텍스트 박스 | X2: 띄어쓰기 | Y2: 영어 | Z2: 기타 외국어 | AA2: 특수문자 | AB2: 어절 | AC2: 박스(<2) | AD2: 다단 의심 | AE2: 다단 여부 | AF2: 난이도 | AG2: 특이사항
A3: SS0001 | B3: 도서1 | G3: pdf | I3: 55 | J3: 2 | K3: 53 | L3: =IF((K3-J3)>0, K3-J3+1, 0) -> 52 | M3: fitz | N3: 288 | AE3: 다단 도서 | AF3: A
A4: SS0002 | B4: 도서2 | G4: epub | I4: 44 | J4: 5 | K4: 40 | L4: =IF((K4-J4)>0, K4-J4+1, 0) -> 36 | M4: gemini | N4: 323 | AE4: 일부 존재 | AF4: C
A5: SS0003 | B5: 도서3 | I5: 100 | J5: 8 | K5: 91 | L5: =IF((K5-J5)>0, K5-J5+1, 0) -> 84 | M5: GPT
A6: SS0004 | B6: 도서4 | I6: 2000 | J6: 3 | K6: 1987 | L6: =IF((K6-J6)>0, K6-J6+1, 0) -> 1985 | M6: 내부 모델
A7: SS0005 | I7: 10 | J7: 1 | K7: 10 | L7: =IF((K7-J7)>0, K7-J7+1, 0) -> 10
A8: SS0006 | I8: 10 | J8: 1 | K8: 10 | L8: =IF((K8-J8)>0, K8-J8+1, 0) -> 10 | N8: 320
A9: SS0007 | I9: 15 | J9: 3 | K9: 15 | L9: =IF((K9-J9)>0, K9-J9+1, 0) -> 13 | N9: 476
A10: SS0008 | L10: =IF((K10-J10)>0, K10-J10+1, 0) -> 0 | N10: 354
A11: SS0009 | L11: =IF((K11-J11)>0, K11-J11+1, 0) -> 0 | N11: 248
A12: SS0010 | L12: =IF((K12-J12)>0, K12-J12+1, 0) -> 0 | N12: 640
A13: SS0011 | L13: =IF((K13-J13)>0, K13-J13+1, 0) -> 0 | N13: 248
A14: SS0012 | L14: =IF((K14-J14)>0, K14-J14+1, 0) -> 0 | N14: 212
A15: SS0013 | L15: =IF((K15-J15)>0, K15-J15+1, 0) -> 0 | N15: 360
A16: SS0014 | L16: =IF((K16-J16)>0, K16-J16+1, 0) -> 0 | N16: 299
A17: SS0015 | L17: =IF((K17-J17)>0, K17-J17+1, 0) -> 0 | N17: 288
A18: SS0016 | L18: =IF((K18-J18)>0, K18-J18+1, 0) -> 0 | N18: 532
A19: SS0017 | L19: =IF((K19-J19)>0, K19-J19+1, 0) -> 0 | N19: 328
A20: SS0018 | L20: =IF((K20-J20)>0, K20-J20+1, 0) -> 0 | N20: 391
A21: SS0019 | L21: =IF((K21-J21)>0, K21-J21+1, 0) -> 0 | N21: 288
... A109: SS0107 | L109: =IF((K109-J109)>0, K109-J109+1, 0) -> 0 | N109: 988

Sheet 3. 도서별 작업 현황
A1: ID | B1: 도서명 | C1: 작업 페이지 | D1: 난이도 | E1: 추출 방식 | F1: BBOX 분배 | G1: BBOX 완료 | H1: BBOX 작업자 | I1: BBOX 작업 상태 | J1: BBOX 검수자 | K1: OCR 분배 | L1: OCR 완료 | M1: OCR 작업자 | N1: OCR 작업 상태 | O1: OCR 검수자 | P1: 수식표 분배 | Q1: 수식표 완료 | R1: 수식표 작업 상태 | S1: 최종 폴더 | T1: 정렬 검사 | U1: 최종 검수자 | V1: WER 검수 상태 | W1: WER 검수자 | X1: WER 검수 결과 | Y1: 납품 전 체크리스트 | Z1: 납품 차수 | AA1: 비고
A2: ='2. 도서 정보'!A3 -> SS0001 | B2: {=_xludf.XLOOKUP($A2,도서_정보[ID],도서_정보[도서명],"")} -> #NAME? | C2: {=_xludf.XLOOKUP($A2,도서_정보[ID],도서_정보[작업 페이지],"")} -> #NAME? | D2: {=_xludf.XLOOKUP($A2,도서_정보[ID],도서_정보[난이도],"")} -> #NAME? | E2: {=_xludf.XLOOKUP($A2,도서_정보[ID],도서_정보[추출 방식],"")} -> #NAME? | F2: 46094.685 | G2: 46094.66 | H2: 작업자2(pmadmin162) | I2: 검수 완료 | J2: PM | K2: 46094.66 | L2: 46094.66 | M2: 작업자1(abc) | N2: 작업 완료 | O2: PM | P2: 46094.661 | Q2: 46094.661 | R2: 작업 완료 | S2: 업로드X | T2: FALSE | W2: DA1 | X2: {=_xludf.XLOOKUP(A2,'WER 로그'!A:A,'WER 로그'!I:I,"")} -> #NAME? | Y2: {=IF(AND(_xludf.XLOOKUP(A2,'5. 납품 전 체크리스트'!A:A,'5. 납품 전 체크리스트'!D:M,"",0)),TRUE,FALSE)} -> #NAME? | Z2: 샘플 납품
A3: ='2. 도서 정보'!A4 -> SS0002 | B3: {=_xludf.XLOOKUP($A3,도서_정보[ID],도서_정보[도서명],"")} -> #NAME? | C3: {=_xludf.XLOOKUP($A3,도서_정보[ID],도서_정보[작업 페이지],"")} -> #NAME? | D3: {=_xludf.XLOOKUP($A3,도서_정보[ID],도서_정보[난이도],"")} -> #NAME? | E3: {=_xludf.XLOOKUP($A3,도서_정보[ID],도서_정보[추출 방식],"")} -> #NAME? | S3: 업로드X | T3: FALSE | X3: {=_xludf.XLOOKUP(A3,'WER 로그'!A:A,'WER 로그'!I:I,"")} -> #NAME? | Y3: {=IF(AND(_xludf.XLOOKUP(A3,'5. 납품 전 체크리스트'!A:A,'5. 납품 전 체크리스트'!D:M,"",0)),TRUE,FALSE)} -> #NAME? | Z3: 최종 납품
A4: ='2. 도서 정보'!A5 -> SS0003 | B4: {=_xludf.XLOOKUP($A4,도서_정보[ID],도서_정보[도서명],"")} -> #NAME? | C4: {=_xludf.XLOOKUP($A4,도서_정보[ID],도서_정보[작업 페이지],"")} -> #NAME? | D4: {=_xludf.XLOOKUP($A4,도서_정보[ID],도서_정보[난이도],"")} -> #NAME? | E4: {=_xludf.XLOOKUP($A4,도서_정보[ID],도서_정보[추출 방식],"")} -> #NAME? | S4: 업로드X | T4: FALSE | X4: {=_xludf.XLOOKUP(A4,'WER 로그'!A:A,'WER 로그'!I:I,"")} -> #NAME? | Y4: {=IF(AND(_xludf.XLOOKUP(A4,'5. 납품 전 체크리스트'!A:A,'5. 납품 전 체크리스트'!D:M,"",0)),TRUE,FALSE)} -> #NAME?
A5: ='2. 도서 정보'!A6 -> SS0004 | B5: {=_xludf.XLOOKUP($A5,도서_정보[ID],도서_정보[도서명],"")} -> #NAME? | C5: {=_xludf.XLOOKUP($A5,도서_정보[ID],도서_정보[작업 페이지],"")} -> #NAME? | D5: {=_xludf.XLOOKUP($A5,도서_정보[ID],도서_정보[난이도],"")} -> #NAME? | E5: {=_xludf.XLOOKUP($A5,도서_정보[ID],도서_정보[추출 방식],"")} -> #NAME? | T5: FALSE | X5: {=_xludf.XLOOKUP(A5,'WER 로그'!A:A,'WER 로그'!I:I,"")} -> #NAME? | Y5: {=IF(AND(_xludf.XLOOKUP(A5,'5. 납품 전 체크리스트'!A:A,'5. 납품 전 체크리스트'!D:M,"",0)),TRUE,FALSE)} -> #NAME?
A6: ='2. 도서 정보'!A7 -> SS0005 | B6: {=_xludf.XLOOKUP($A6,도서_정보[ID],도서_정보[도서명],"")} -> #NAME? | C6: {=_xludf.XLOOKUP($A6,도서_정보[ID],도서_정보[작업 페이지],"")} -> #NAME? | D6: {=_xludf.XLOOKUP($A6,도서_정보[ID],도서_정보[난이도],"")} -> #NAME? | E6: {=_xludf.XLOOKUP($A6,도서_정보[ID],도서_정보[추출 방식],"")} -> #NAME? | T6: FALSE | X6: {=_xludf.XLOOKUP(A6,'WER 로그'!A:A,'WER 로그'!I:I,"")} -> #NAME? | Y6: {=IF(AND(_xludf.XLOOKUP(A6,'5. 납품 전 체크리스트'!A:A,'5. 납품 전 체크리스트'!D:M,"",0)),TRUE,FALSE)} -> #NAME?
A7: ='2. 도서 정보'!A8 -> SS0006 | B7: {=_xludf.XLOOKUP($A7,도서_정보[ID],도서_정보[도서명],"")} -> #NAME? | C7: {=_xludf.XLOOKUP($A7,도서_정보[ID],도서_정보[작업 페이지],"")} -> #NAME? | D7: {=_xludf.XLOOKUP($A7,도서_정보[ID],도서_정보[난이도],"")} -> #NAME? | E7: {=_xludf.XLOOKUP($A7,도서_정보[ID],도서_정보[추출 방식],"")} -> #NAME? | S7: 업로드X | T7: FALSE | X7: {=_xludf.XLOOKUP(A7,'WER 로그'!A:A,'WER 로그'!I:I,"")} -> #NAME? | Y7: {=IF(AND(_xludf.XLOOKUP(A7,'5. 납품 전 체크리스트'!A:A,'5. 납품 전 체크리스트'!D:M,"",0)),TRUE,FALSE)} -> #NAME?
A8: ='2. 도서 정보'!A9 -> SS0007 | B8: {=_xludf.XLOOKUP($A8,도서_정보[ID],도서_정보[도서명],"")} -> #NAME? | C8: {=_xludf.XLOOKUP($A8,도서_정보[ID],도서_정보[작업 페이지],"")} -> #NAME? | D8: {=_xludf.XLOOKUP($A8,도서_정보[ID],도서_정보[난이도],"")} -> #NAME? | E8: {=_xludf.XLOOKUP($A8,도서_정보[ID],도서_정보[추출 방식],"")} -> #NAME? | S8: 업로드X | T8: FALSE | X8: {=_xludf.XLOOKUP(A8,'WER 로그'!A:A,'WER 로그'!I:I,"")} -> #NAME? | Y8: {=IF(AND(_xludf.XLOOKUP(A8,'5. 납품 전 체크리스트'!A:A,'5. 납품 전 체크리스트'!D:M,"",0)),TRUE,FALSE)} -> #NAME?
A9: ='2. 도서 정보'!A10 -> SS0008 | B9: {=_xludf.XLOOKUP($A9,도서_정보[ID],도서_정보[도서명],"")} -> #NAME? | C9: {=_xludf.XLOOKUP($A9,도서_정보[ID],도서_정보[작업 페이지],"")} -> #NAME? | D9: {=_xludf.XLOOKUP($A9,도서_정보[ID],도서_정보[난이도],"")} -> #NAME? | E9: {=_xludf.XLOOKUP($A9,도서_정보[ID],도서_정보[추출 방식],"")} -> #NAME? | S9: 업로드X | T9: FALSE | X9: {=_xludf.XLOOKUP(A9,'WER 로그'!A:A,'WER 로그'!I:I,"")} -> #NAME? | Y9: {=IF(AND(_xludf.XLOOKUP(A9,'5. 납품 전 체크리스트'!A:A,'5. 납품 전 체크리스트'!D:M,"",0)),TRUE,FALSE)} -> #NAME?
A10: ='2. 도서 정보'!A11 -> SS0009 | B10: {=_xludf.XLOOKUP($A10,도서_정보[ID],도서_정보[도서명],"")} -> #NAME? | C10: {=_xludf.XLOOKUP($A10,도서_정보[ID],도서_정보[작업 페이지],"")} -> #NAME? | D10: {=_xludf.XLOOKUP($A10,도서_정보[ID],도서_정보[난이도],"")} -> #NAME? | E10: {=_xludf.XLOOKUP($A10,도서_정보[ID],도서_정보[추출 방식],"")} -> #NAME? | S10: 업로드X | T10: FALSE | X10: {=_xludf.XLOOKUP(A10,'WER 로그'!A:A,'WER 로그'!I:I,"")} -> #NAME? | Y10: {=IF(AND(_xludf.XLOOKUP(A10,'5. 납품 전 체크리스트'!A:A,'5. 납품 전 체크리스트'!D:M,"",0)),TRUE,FALSE)} -> #NAME?
A11: ='2. 도서 정보'!A12 -> SS0010 | B11: {=_xludf.XLOOKUP($A11,도서_정보[ID],도서_정보[도서명],"")} -> #NAME? | C11: {=_xludf.XLOOKUP($A11,도서_정보[ID],도서_정보[작업 페이지],"")} -> #NAME? | D11: {=_xludf.XLOOKUP($A11,도서_정보[ID],도서_정보[난이도],"")} -> #NAME? | E11: {=_xludf.XLOOKUP($A11,도서_정보[ID],도서_정보[추출 방식],"")} -> #NAME? | S11: 업로드X | T11: FALSE | X11: {=_xludf.XLOOKUP(A11,'WER 로그'!A:A,'WER 로그'!I:I,"")} -> #NAME? | Y11: {=IF(AND(_xludf.XLOOKUP(A11,'5. 납품 전 체크리스트'!A:A,'5. 납품 전 체크리스트'!D:M,"",0)),TRUE,FALSE)} -> #NAME?
A12: ='2. 도서 정보'!A13 -> SS0011 | B12: {=_xludf.XLOOKUP($A12,도서_정보[ID],도서_정보[도서명],"")} -> #NAME? | C12: {=_xludf.XLOOKUP($A12,도서_정보[ID],도서_정보[작업 페이지],"")} -> #NAME? | D12: {=_xludf.XLOOKUP($A12,도서_정보[ID],도서_정보[난이도],"")} -> #NAME? | E12: {=_xludf.XLOOKUP($A12,도서_정보[ID],도서_정보[추출 방식],"")} -> #NAME? | S12: 업로드X | T12: FALSE | X12: {=_xludf.XLOOKUP(A12,'WER 로그'!A:A,'WER 로그'!I:I,"")} -> #NAME? | Y12: {=IF(AND(_xludf.XLOOKUP(A12,'5. 납품 전 체크리스트'!A:A,'5. 납품 전 체크리스트'!D:M,"",0)),TRUE,FALSE)} -> #NAME?
A13: ='2. 도서 정보'!A14 -> SS0012 | B13: {=_xludf.XLOOKUP($A13,도서_정보[ID],도서_정보[도서명],"")} -> #NAME? | C13: {=_xludf.XLOOKUP($A13,도서_정보[ID],도서_정보[작업 페이지],"")} -> #NAME? | D13: {=_xludf.XLOOKUP($A13,도서_정보[ID],도서_정보[난이도],"")} -> #NAME? | E13: {=_xludf.XLOOKUP($A13,도서_정보[ID],도서_정보[추출 방식],"")} -> #NAME? | S13: 업로드X | T13: FALSE | X13: {=_xludf.XLOOKUP(A13,'WER 로그'!A:A,'WER 로그'!I:I,"")} -> #NAME? | Y13: {=IF(AND(_xludf.XLOOKUP(A13,'5. 납품 전 체크리스트'!A:A,'5. 납품 전 체크리스트'!D:M,"",0)),TRUE,FALSE)} -> #NAME?
A14: ='2. 도서 정보'!A15 -> SS0013 | B14: {=_xludf.XLOOKUP($A14,도서_정보[ID],도서_정보[도서명],"")} -> #NAME? | C14: {=_xludf.XLOOKUP($A14,도서_정보[ID],도서_정보[작업 페이지],"")} -> #NAME? | D14: {=_xludf.XLOOKUP($A14,도서_정보[ID],도서_정보[난이도],"")} -> #NAME? | E14: {=_xludf.XLOOKUP($A14,도서_정보[ID],도서_정보[추출 방식],"")} -> #NAME? | S14: 업로드X | T14: FALSE | X14: {=_xludf.XLOOKUP(A14,'WER 로그'!A:A,'WER 로그'!I:I,"")} -> #NAME? | Y14: {=IF(AND(_xludf.XLOOKUP(A14,'5. 납품 전 체크리스트'!A:A,'5. 납품 전 체크리스트'!D:M,"",0)),TRUE,FALSE)} -> #NAME?
A15: ='2. 도서 정보'!A16 -> SS0014 | B15: {=_xludf.XLOOKUP($A15,도서_정보[ID],도서_정보[도서명],"")} -> #NAME? | C15: {=_xludf.XLOOKUP($A15,도서_정보[ID],도서_정보[작업 페이지],"")} -> #NAME? | D15: {=_xludf.XLOOKUP($A15,도서_정보[ID],도서_정보[난이도],"")} -> #NAME? | E15: {=_xludf.XLOOKUP($A15,도서_정보[ID],도서_정보[추출 방식],"")} -> #NAME? | S15: 업로드X | T15: FALSE | X15: {=_xludf.XLOOKUP(A15,'WER 로그'!A:A,'WER 로그'!I:I,"")} -> #NAME? | Y15: {=IF(AND(_xludf.XLOOKUP(A15,'5. 납품 전 체크리스트'!A:A,'5. 납품 전 체크리스트'!D:M,"",0)),TRUE,FALSE)} -> #NAME?
A16: ='2. 도서 정보'!A17 -> SS0015 | B16: {=_xludf.XLOOKUP($A16,도서_정보[ID],도서_정보[도서명],"")} -> #NAME? | C16: {=_xludf.XLOOKUP($A16,도서_정보[ID],도서_정보[작업 페이지],"")} -> #NAME? | D16: {=_xludf.XLOOKUP($A16,도서_정보[ID],도서_정보[난이도],"")} -> #NAME? | E16: {=_xludf.XLOOKUP($A16,도서_정보[ID],도서_정보[추출 방식],"")} -> #NAME? | S16: 업로드X | T16: FALSE | X16: {=_xludf.XLOOKUP(A16,'WER 로그'!A:A,'WER 로그'!I:I,"")} -> #NAME? | Y16: {=IF(AND(_xludf.XLOOKUP(A16,'5. 납품 전 체크리스트'!A:A,'5. 납품 전 체크리스트'!D:M,"",0)),TRUE,FALSE)} -> #NAME?
A17: ='2. 도서 정보'!A18 -> SS0016 | B17: {=_xludf.XLOOKUP($A17,도서_정보[ID],도서_정보[도서명],"")} -> #NAME? | C17: {=_xludf.XLOOKUP($A17,도서_정보[ID],도서_정보[작업 페이지],"")} -> #NAME? | D17: {=_xludf.XLOOKUP($A17,도서_정보[ID],도서_정보[난이도],"")} -> #NAME? | E17: {=_xludf.XLOOKUP($A17,도서_정보[ID],도서_정보[추출 방식],"")} -> #NAME? | T17: FALSE | X17: {=_xludf.XLOOKUP(A17,'WER 로그'!A:A,'WER 로그'!I:I,"")} -> #NAME? | Y17: {=IF(AND(_xludf.XLOOKUP(A17,'5. 납품 전 체크리스트'!A:A,'5. 납품 전 체크리스트'!D:M,"",0)),TRUE,FALSE)} -> #NAME?
A18: ='2. 도서 정보'!A19 -> SS0017 | B18: {=_xludf.XLOOKUP($A18,도서_정보[ID],도서_정보[도서명],"")} -> #NAME? | C18: {=_xludf.XLOOKUP($A18,도서_정보[ID],도서_정보[작업 페이지],"")} -> #NAME? | D18: {=_xludf.XLOOKUP($A18,도서_정보[ID],도서_정보[난이도],"")} -> #NAME? | E18: {=_xludf.XLOOKUP($A18,도서_정보[ID],도서_정보[추출 방식],"")} -> #NAME? | T18: FALSE | X18: {=_xludf.XLOOKUP(A18,'WER 로그'!A:A,'WER 로그'!I:I,"")} -> #NAME? | Y18: {=IF(AND(_xludf.XLOOKUP(A18,'5. 납품 전 체크리스트'!A:A,'5. 납품 전 체크리스트'!D:M,"",0)),TRUE,FALSE)} -> #NAME?
A19: ='2. 도서 정보'!A20 -> SS0018 | B19: {=_xludf.XLOOKUP($A19,도서_정보[ID],도서_정보[도서명],"")} -> #NAME? | C19: {=_xludf.XLOOKUP($A19,도서_정보[ID],도서_정보[작업 페이지],"")} -> #NAME? | D19: {=_xludf.XLOOKUP($A19,도서_정보[ID],도서_정보[난이도],"")} -> #NAME? | E19: {=_xludf.XLOOKUP($A19,도서_정보[ID],도서_정보[추출 방식],"")} -> #NAME? | T19: FALSE | X19: {=_xludf.XLOOKUP(A19,'WER 로그'!A:A,'WER 로그'!I:I,"")} -> #NAME? | Y19: {=IF(AND(_xludf.XLOOKUP(A19,'5. 납품 전 체크리스트'!A:A,'5. 납품 전 체크리스트'!D:M,"",0)),TRUE,FALSE)} -> #NAME?
A20: ='2. 도서 정보'!A21 -> SS0019 | B20: {=_xludf.XLOOKUP($A20,도서_정보[ID],도서_정보[도서명],"")} -> #NAME? | C20: {=_xludf.XLOOKUP($A20,도서_정보[ID],도서_정보[작업 페이지],"")} -> #NAME? | D20: {=_xludf.XLOOKUP($A20,도서_정보[ID],도서_정보[난이도],"")} -> #NAME? | E20: {=_xludf.XLOOKUP($A20,도서_정보[ID],도서_정보[추출 방식],"")} -> #NAME? | T20: FALSE | X20: {=_xludf.XLOOKUP(A20,'WER 로그'!A:A,'WER 로그'!I:I,"")} -> #NAME? | Y20: {=IF(AND(_xludf.XLOOKUP(A20,'5. 납품 전 체크리스트'!A:A,'5. 납품 전 체크리스트'!D:M,"",0)),TRUE,FALSE)} -> #NAME?
A21: ='2. 도서 정보'!A22 -> SS0020 | B21: {=_xludf.XLOOKUP($A21,도서_정보[ID],도서_정보[도서명],"")} -> #NAME? | C21: {=_xludf.XLOOKUP($A21,도서_정보[ID],도서_정보[작업 페이지],"")} -> #NAME? | D21: {=_xludf.XLOOKUP($A21,도서_정보[ID],도서_정보[난이도],"")} -> #NAME? | E21: {=_xludf.XLOOKUP($A21,도서_정보[ID],도서_정보[추출 방식],"")} -> #NAME? | T21: FALSE | X21: {=_xludf.XLOOKUP(A21,'WER 로그'!A:A,'WER 로그'!I:I,"")} -> #NAME? | Y21: {=IF(AND(_xludf.XLOOKUP(A21,'5. 납품 전 체크리스트'!A:A,'5. 납품 전 체크리스트'!D:M,"",0)),TRUE,FALSE)} -> #NAME?
A22: ='2. 도서 정보'!A23 -> SS0021 | B22: {=_xludf.XLOOKUP($A22,도서_정보[ID],도서_정보[도서명],"")} -> #NAME? | C22: {=_xludf.XLOOKUP($A22,도서_정보[ID],도서_정보[작업 페이지],"")} -> #NAME? | D22: {=_xludf.XLOOKUP($A22,도서_정보[ID],도서_정보[난이도],"")} -> #NAME? | E22: {=_xludf.XLOOKUP($A22,도서_정보[ID],도서_정보[추출 방식],"")} -> #NAME? | T22: FALSE | X22: {=_xludf.XLOOKUP(A22,'WER 로그'!A:A,'WER 로그'!I:I,"")} -> #NAME? | Y22: {=IF(AND(_xludf.XLOOKUP(A22,'5. 납품 전 체크리스트'!A:A,'5. 납품 전 체크리스트'!D:M,"",0)),TRUE,FALSE)} -> #NAME?
A23: ='2. 도서 정보'!A24 -> SS0022 | B23: {=_xludf.XLOOKUP($A23,도서_정보[ID],도서_정보[도서명],"")} -> #NAME? | C23: {=_xludf.XLOOKUP($A23,도서_정보[ID],도서_정보[작업 페이지],"")} -> #NAME? | D23: {=_xludf.XLOOKUP($A23,도서_정보[ID],도서_정보[난이도],"")} -> #NAME? | E23: {=_xludf.XLOOKUP($A23,도서_정보[ID],도서_정보[추출 방식],"")} -> #NAME? | T23: FALSE | X23: {=_xludf.XLOOKUP(A23,'WER 로그'!A:A,'WER 로그'!I:I,"")} -> #NAME? | Y23: {=IF(AND(_xludf.XLOOKUP(A23,'5. 납품 전 체크리스트'!A:A,'5. 납품 전 체크리스트'!D:M,"",0)),TRUE,FALSE)} -> #NAME?
A24: ='2. 도서 정보'!A25 -> SS0023 | B24: {=_xludf.XLOOKUP($A24,도서_정보[ID],도서_정보[도서명],"")} -> #NAME? | C24: {=_xludf.XLOOKUP($A24,도서_정보[ID],도서_정보[작업 페이지],"")} -> #NAME? | D24: {=_xludf.XLOOKUP($A24,도서_정보[ID],도서_정보[난이도],"")} -> #NAME? | E24: {=_xludf.XLOOKUP($A24,도서_정보[ID],도서_정보[추출 방식],"")} -> #NAME? | T24: FALSE | X24: {=_xludf.XLOOKUP(A24,'WER 로그'!A:A,'WER 로그'!I:I,"")} -> #NAME? | Y24: {=IF(AND(_xludf.XLOOKUP(A24,'5. 납품 전 체크리스트'!A:A,'5. 납품 전 체크리스트'!D:M,"",0)),TRUE,FALSE)} -> #NAME?
A25: ='2. 도서 정보'!A26 -> SS0024 | B25: {=_xludf.XLOOKUP($A25,도서_정보[ID],도서_정보[도서명],"")} -> #NAME? | C25: {=_xludf.XLOOKUP($A25,도서_정보[ID],도서_정보[작업 페이지],"")} -> #NAME? | D25: {=_xludf.XLOOKUP($A25,도서_정보[ID],도서_정보[난이도],"")} -> #NAME? | E25: {=_xludf.XLOOKUP($A25,도서_정보[ID],도서_정보[추출 방식],"")} -> #NAME? | T25: FALSE | X25: {=_xludf.XLOOKUP(A25,'WER 로그'!A:A,'WER 로그'!I:I,"")} -> #NAME? | Y25: {=IF(AND(_xludf.XLOOKUP(A25,'5. 납품 전 체크리스트'!A:A,'5. 납품 전 체크리스트'!D:M,"",0)),TRUE,FALSE)} -> #NAME?
A26: ='2. 도서 정보'!A27 -> SS0025 | B26: {=_xludf.XLOOKUP($A26,도서_정보[ID],도서_정보[도서명],"")} -> #NAME? | C26: {=_xludf.XLOOKUP($A26,도서_정보[ID],도서_정보[작업 페이지],"")} -> #NAME? | D26: {=_xludf.XLOOKUP($A26,도서_정보[ID],도서_정보[난이도],"")} -> #NAME? | E26: {=_xludf.XLOOKUP($A26,도서_정보[ID],도서_정보[추출 방식],"")} -> #NAME? | T26: FALSE | X26: {=_xludf.XLOOKUP(A26,'WER 로그'!A:A,'WER 로그'!I:I,"")} -> #NAME? | Y26: {=IF(AND(_xludf.XLOOKUP(A26,'5. 납품 전 체크리스트'!A:A,'5. 납품 전 체크리스트'!D:M,"",0)),TRUE,FALSE)} -> #NAME?
A27: ='2. 도서 정보'!A28 -> SS0026 | B27: {=_xludf.XLOOKUP($A27,도서_정보[ID],도서_정보[도서명],"")} -> #NAME? | C27: {=_xludf.XLOOKUP($A27,도서_정보[ID],도서_정보[작업 페이지],"")} -> #NAME? | D27: {=_xludf.XLOOKUP($A27,도서_정보[ID],도서_정보[난이도],"")} -> #NAME? | E27: {=_xludf.XLOOKUP($A27,도서_정보[ID],도서_정보[추출 방식],"")} -> #NAME? | T27: FALSE | X27: {=_xludf.XLOOKUP(A27,'WER 로그'!A:A,'WER 로그'!I:I,"")} -> #NAME? | Y27: {=IF(AND(_xludf.XLOOKUP(A27,'5. 납품 전 체크리스트'!A:A,'5. 납품 전 체크리스트'!D:M,"",0)),TRUE,FALSE)} -> #NAME?
A28: ='2. 도서 정보'!A29 -> SS0027 | B28: {=_xludf.XLOOKUP($A28,도서_정보[ID],도서_정보[도서명],"")} -> #NAME? | C28: {=_xludf.XLOOKUP($A28,도서_정보[ID],도서_정보[작업 페이지],"")} -> #NAME? | D28: {=_xludf.XLOOKUP($A28,도서_정보[ID],도서_정보[난이도],"")} -> #NAME? | E28: {=_xludf.XLOOKUP($A28,도서_정보[ID],도서_정보[추출 방식],"")} -> #NAME? | T28: FALSE | X28: {=_xludf.XLOOKUP(A28,'WER 로그'!A:A,'WER 로그'!I:I,"")} -> #NAME? | Y28: {=IF(AND(_xludf.XLOOKUP(A28,'5. 납품 전 체크리스트'!A:A,'5. 납품 전 체크리스트'!D:M,"",0)),TRUE,FALSE)} -> #NAME?
... A108: ='2. 도서 정보'!A109 -> SS0107 | B108: {=_xludf.XLOOKUP($A108,도서_정보[ID],도서_정보[도서명],"")} -> #NAME? | C108: {=_xludf.XLOOKUP($A108,도서_정보[ID],도서_정보[작업 페이지],"")} -> #NAME? | D108: {=_xludf.XLOOKUP($A108,도서_정보[ID],도서_정보[난이도],"")} -> #NAME? | E108: {=_xludf.XLOOKUP($A108,도서_정보[ID],도서_정보[추출 방식],"")} -> #NAME? | T108: FALSE | X108: {=_xludf.XLOOKUP(A108,'WER 로그'!A:A,'WER 로그'!I:I,"")} -> #NAME? | Y108: {=IF(AND(_xludf.XLOOKUP(A108,'5. 납품 전 체크리스트'!A:A,'5. 납품 전 체크리스트'!D:M,"",0)),TRUE,FALSE)} -> #NAME?

Sheet 4. 작업자 관리
A1: 이름(아이디) | B1: 이름 | C1: 아이디 | D1: 이메일 | E1: 작업 중 폴더 | F1: 작업 단계 | G1: 현재 작업량 | H1: 전체 페이지 | I1: BBOX 작업량 | J1: OCR 작업량 | K1: 테스트 평가 | L1: 최종 평가 | M1: 비고 | O1: 이름 | P1: 이메일 | Q1: 아이디 | R1: 수식표 작업량 | S1: 테스트 평가 | T1: 평가 | U1: 비고
A2: =CONCATENATE(B2,"(",C2,")") -> 작업자1(abc) | B2: 작업자1 | C2: abc | K2: 0 | L2: 0 | S2: 0 | T2: 0
A3: =CONCATENATE(B3,"(",C3,")") -> 작업자2(pmadmin162) | B3: 작업자2 | C3: pmadmin162 | K3: 0 | L3: 0 | S3: 0 | T3: 0
A4: =CONCATENATE(B4,"(",C4,")") -> () | K4: 0 | L4: 0 | S4: 0 | T4: 0
A5: =CONCATENATE(B5,"(",C5,")") -> () | K5: 0 | L5: 0 | S5: 0 | T5: 0
A6: =CONCATENATE(B6,"(",C6,")") -> () | K6: 0 | L6: 0 | S6: 0 | T6: 0
A7: =CONCATENATE(B7,"(",C7,")") -> () | K7: 0 | L7: 0 | S7: 0 | T7: 0
A8: =CONCATENATE(B8,"(",C8,")") -> () | K8: 0 | L8: 0 | S8: 0 | T8: 0
A9: =CONCATENATE(B9,"(",C9,")") -> () | K9: 0 | L9: 0 | S9: 0 | T9: 0
A10: =CONCATENATE(B10,"(",C10,")") -> () | K10: 0 | L10: 0 | S10: 0 | T10: 0
A11: =CONCATENATE(B11,"(",C11,")") -> () | K11: 0 | L11: 0 | S11: 0 | T11: 0
A12: =CONCATENATE(B12,"(",C12,")") -> () | K12: 0 | L12: 0 | S12: 0 | T12: 0
A13: =CONCATENATE(B13,"(",C13,")") -> () | K13: 0 | L13: 0 | S13: 0 | T13: 0
A14: =CONCATENATE(B14,"(",C14,")") -> () | K14: 0 | L14: 0 | S14: 0 | T14: 0
A15: =CONCATENATE(B15,"(",C15,")") -> () | K15: 0 | L15: 0 | S15: 0 | T15: 0

Sheet 5. 납품 전 체크리스트
A1: ID | B1: 도서명 | C1: 작업 페이지 | D1: 박스 포함 관계 검사 | E1: 빈 라벨 검사 | F1: (파싱 전) 태그 페어 검사 | G1: 노이즈 문자 검사 | H1: 수식표 환경 매칭 검사 | I1: 파싱 | J1: 데이터 스키마 유효성 검사 | K1: (파싱 후) 태그 페어 검사 | L1: 크롭 이미지 육안 검사 | M1: (문제집 유형) 문제 유효성 검사 | N1: 납품 차수 | O1: 특이사항
A2: =IFERROR(__xludf.DUMMYFUNCTION("filter(도서_정보[ID], len(도서_정보[ID]))"),"SS0001") -> SS0001 | B2: {=_xludf.XLOOKUP(A2, 도서_정보[ID], 도서_정보[도서명], "")} -> #NAME? | C2: {=_xludf.XLOOKUP(A2, 도서_정보[ID], 도서_정보[작업 페이지], "")} -> #NAME? | D2: FALSE | E2: FALSE | F2: FALSE | G2: FALSE | H2: FALSE | I2: FALSE | J2: FALSE | K2: FALSE | L2: FALSE | M2: FALSE | N2: {=_xludf.XLOOKUP(A2,'3. 도서별 작업 현황'!A:A,'3. 도서별 작업 현황'!Z:Z,"")} -> #NAME?
A3: =IFERROR(__xludf.DUMMYFUNCTION("""COMPUTED_VALUE"""),"SS0002") -> SS0002 | B3: {=_xludf.XLOOKUP(A3, 도서_정보[ID], 도서_정보[도서명], "")} -> #NAME? | C3: {=_xludf.XLOOKUP(A3, 도서_정보[ID], 도서_정보[작업 페이지], "")} -> #NAME? | D3: FALSE | E3: FALSE | F3: FALSE | G3: FALSE | H3: FALSE | I3: FALSE | J3: FALSE | K3: FALSE | L3: FALSE | M3: FALSE | N3: {=_xludf.XLOOKUP(A3,'3. 도서별 작업 현황'!A:A,'3. 도서별 작업 현황'!Z:Z,"")} -> #NAME?
A4: =IFERROR(__xludf.DUMMYFUNCTION("""COMPUTED_VALUE"""),"SS0003") -> SS0003 | B4: {=_xludf.XLOOKUP(A4, 도서_정보[ID], 도서_정보[도서명], "")} -> #NAME? | C4: {=_xludf.XLOOKUP(A4, 도서_정보[ID], 도서_정보[작업 페이지], "")} -> #NAME? | D4: FALSE | E4: FALSE | F4: FALSE | G4: FALSE | H4: FALSE | I4: FALSE | J4: FALSE | K4: FALSE | L4: FALSE | M4: FALSE | N4: {=_xludf.XLOOKUP(A4,'3. 도서별 작업 현황'!A:A,'3. 도서별 작업 현황'!Z:Z,"")} -> #NAME?
A5: =IFERROR(__xludf.DUMMYFUNCTION("""COMPUTED_VALUE"""),"SS0004") -> SS0004 | B5: {=_xludf.XLOOKUP(A5, 도서_정보[ID], 도서_정보[도서명], "")} -> #NAME? | C5: {=_xludf.XLOOKUP(A5, 도서_정보[ID], 도서_정보[작업 페이지], "")} -> #NAME? | D5: FALSE | E5: FALSE | F5: FALSE | G5: FALSE | H5: FALSE | I5: FALSE | J5: FALSE | K5: FALSE | L5: FALSE | M5: FALSE | N5: {=_xludf.XLOOKUP(A5,'3. 도서별 작업 현황'!A:A,'3. 도서별 작업 현황'!Z:Z,"")} -> #NAME?
A6: =IFERROR(__xludf.DUMMYFUNCTION("""COMPUTED_VALUE"""),"SS0005") -> SS0005 | B6: {=_xludf.XLOOKUP(A6, 도서_정보[ID], 도서_정보[도서명], "")} -> #NAME? | C6: {=_xludf.XLOOKUP(A6, 도서_정보[ID], 도서_정보[작업 페이지], "")} -> #NAME? | D6: FALSE | E6: FALSE | F6: FALSE | G6: FALSE | H6: FALSE | I6: FALSE | J6: FALSE | K6: FALSE | L6: FALSE | M6: FALSE | N6: {=_xludf.XLOOKUP(A6,'3. 도서별 작업 현황'!A:A,'3. 도서별 작업 현황'!Z:Z,"")} -> #NAME?
A7: =IFERROR(__xludf.DUMMYFUNCTION("""COMPUTED_VALUE"""),"SS0006") -> SS0006 | B7: {=_xludf.XLOOKUP(A7, 도서_정보[ID], 도서_정보[도서명], "")} -> #NAME? | C7: {=_xludf.XLOOKUP(A7, 도서_정보[ID], 도서_정보[작업 페이지], "")} -> #NAME? | D7: FALSE | E7: FALSE | F7: FALSE | G7: FALSE | H7: FALSE | I7: FALSE | J7: FALSE | K7: FALSE | L7: FALSE | M7: FALSE | N7: {=_xludf.XLOOKUP(A7,'3. 도서별 작업 현황'!A:A,'3. 도서별 작업 현황'!Z:Z,"")} -> #NAME?
A8: =IFERROR(__xludf.DUMMYFUNCTION("""COMPUTED_VALUE"""),"SS0007") -> SS0007 | B8: {=_xludf.XLOOKUP(A8, 도서_정보[ID], 도서_정보[도서명], "")} -> #NAME? | C8: {=_xludf.XLOOKUP(A8, 도서_정보[ID], 도서_정보[작업 페이지], "")} -> #NAME? | D8: FALSE | E8: FALSE | F8: FALSE | G8: FALSE | H8: FALSE | I8: FALSE | J8: FALSE | K8: FALSE | L8: FALSE | M8: FALSE | N8: {=_xludf.XLOOKUP(A8,'3. 도서별 작업 현황'!A:A,'3. 도서별 작업 현황'!Z:Z,"")} -> #NAME?
A9: =IFERROR(__xludf.DUMMYFUNCTION("""COMPUTED_VALUE"""),"SS0008") -> SS0008 | B9: {=_xludf.XLOOKUP(A9, 도서_정보[ID], 도서_정보[도서명], "")} -> #NAME? | C9: {=_xludf.XLOOKUP(A9, 도서_정보[ID], 도서_정보[작업 페이지], "")} -> #NAME? | D9: FALSE | E9: FALSE | F9: FALSE | G9: FALSE | H9: FALSE | I9: FALSE | J9: FALSE | K9: FALSE | L9: FALSE | M9: FALSE | N9: {=_xludf.XLOOKUP(A9,'3. 도서별 작업 현황'!A:A,'3. 도서별 작업 현황'!Z:Z,"")} -> #NAME?
A10: =IFERROR(__xludf.DUMMYFUNCTION("""COMPUTED_VALUE"""),"SS0009") -> SS0009 | B10: {=_xludf.XLOOKUP(A10, 도서_정보[ID], 도서_정보[도서명], "")} -> #NAME? | C10: {=_xludf.XLOOKUP(A10, 도서_정보[ID], 도서_정보[작업 페이지], "")} -> #NAME? | D10: FALSE | E10: FALSE | F10: FALSE | G10: FALSE | H10: FALSE | I10: FALSE | J10: FALSE | K10: FALSE | L10: FALSE | M10: FALSE | N10: {=_xludf.XLOOKUP(A10,'3. 도서별 작업 현황'!A:A,'3. 도서별 작업 현황'!Z:Z,"")} -> #NAME?
A11: =IFERROR(__xludf.DUMMYFUNCTION("""COMPUTED_VALUE"""),"SS0010") -> SS0010 | B11: {=_xludf.XLOOKUP(A11, 도서_정보[ID], 도서_정보[도서명], "")} -> #NAME? | C11: {=_xludf.XLOOKUP(A11, 도서_정보[ID], 도서_정보[작업 페이지], "")} -> #NAME? | D11: FALSE | E11: FALSE | F11: FALSE | G11: FALSE | H11: FALSE | I11: FALSE | J11: FALSE | K11: FALSE | L11: FALSE | M11: FALSE | N11: {=_xludf.XLOOKUP(A11,'3. 도서별 작업 현황'!A:A,'3. 도서별 작업 현황'!Z:Z,"")} -> #NAME?
A12: =IFERROR(__xludf.DUMMYFUNCTION("""COMPUTED_VALUE"""),"SS0011") -> SS0011 | B12: {=_xludf.XLOOKUP(A12, 도서_정보[ID], 도서_정보[도서명], "")} -> #NAME? | C12: {=_xludf.XLOOKUP(A12, 도서_정보[ID], 도서_정보[작업 페이지], "")} -> #NAME? | D12: FALSE | E12: FALSE | F12: FALSE | G12: FALSE | H12: FALSE | I12: FALSE | J12: FALSE | K12: FALSE | L12: FALSE | M12: FALSE | N12: {=_xludf.XLOOKUP(A12,'3. 도서별 작업 현황'!A:A,'3. 도서별 작업 현황'!Z:Z,"")} -> #NAME?
A13: =IFERROR(__xludf.DUMMYFUNCTION("""COMPUTED_VALUE"""),"SS0012") -> SS0012 | B13: {=_xludf.XLOOKUP(A13, 도서_정보[ID], 도서_정보[도서명], "")} -> #NAME? | C13: {=_xludf.XLOOKUP(A13, 도서_정보[ID], 도서_정보[작업 페이지], "")} -> #NAME? | D13: FALSE | E13: FALSE | F13: FALSE | G13: FALSE | H13: FALSE | I13: FALSE | J13: FALSE | K13: FALSE | L13: FALSE | M13: FALSE | N13: {=_xludf.XLOOKUP(A13,'3. 도서별 작업 현황'!A:A,'3. 도서별 작업 현황'!Z:Z,"")} -> #NAME?
A14: =IFERROR(__xludf.DUMMYFUNCTION("""COMPUTED_VALUE"""),"SS0013") -> SS0013 | B14: {=_xludf.XLOOKUP(A14, 도서_정보[ID], 도서_정보[도서명], "")} -> #NAME? | C14: {=_xludf.XLOOKUP(A14, 도서_정보[ID], 도서_정보[작업 페이지], "")} -> #NAME? | D14: FALSE | E14: FALSE | F14: FALSE | G14: FALSE | H14: FALSE | I14: FALSE | J14: FALSE | K14: FALSE | L14: FALSE | M14: FALSE | N14: {=_xludf.XLOOKUP(A14,'3. 도서별 작업 현황'!A:A,'3. 도서별 작업 현황'!Z:Z,"")} -> #NAME?
A15: =IFERROR(__xludf.DUMMYFUNCTION("""COMPUTED_VALUE"""),"SS0014") -> SS0014 | B15: {=_xludf.XLOOKUP(A15, 도서_정보[ID], 도서_정보[도서명], "")} -> #NAME? | C15: {=_xludf.XLOOKUP(A15, 도서_정보[ID], 도서_정보[작업 페이지], "")} -> #NAME? | D15: FALSE | E15: FALSE | F15: FALSE | G15: FALSE | H15: FALSE | I15: FALSE | J15: FALSE | K15: FALSE | L15: FALSE | M15: FALSE | N15: {=_xludf.XLOOKUP(A15,'3. 도서별 작업 현황'!A:A,'3. 도서별 작업 현황'!Z:Z,"")} -> #NAME?
A16: =IFERROR(__xludf.DUMMYFUNCTION("""COMPUTED_VALUE"""),"SS0015") -> SS0015 | B16: {=_xludf.XLOOKUP(A16, 도서_정보[ID], 도서_정보[도서명], "")} -> #NAME? | C16: {=_xludf.XLOOKUP(A16, 도서_정보[ID], 도서_정보[작업 페이지], "")} -> #NAME? | D16: FALSE | E16: FALSE | F16: FALSE | G16: FALSE | H16: FALSE | I16: FALSE | J16: FALSE | K16: FALSE | L16: FALSE | M16: FALSE | N16: {=_xludf.XLOOKUP(A16,'3. 도서별 작업 현황'!A:A,'3. 도서별 작업 현황'!Z:Z,"")} -> #NAME?
A17: =IFERROR(__xludf.DUMMYFUNCTION("""COMPUTED_VALUE"""),"SS0016") -> SS0016 | B17: {=_xludf.XLOOKUP(A17, 도서_정보[ID], 도서_정보[도서명], "")} -> #NAME? | C17: {=_xludf.XLOOKUP(A17, 도서_정보[ID], 도서_정보[작업 페이지], "")} -> #NAME? | D17: FALSE | E17: FALSE | F17: FALSE | G17: FALSE | H17: FALSE | I17: FALSE | J17: FALSE | K17: FALSE | L17: FALSE | M17: FALSE | N17: {=_xludf.XLOOKUP(A17,'3. 도서별 작업 현황'!A:A,'3. 도서별 작업 현황'!Z:Z,"")} -> #NAME?
A18: =IFERROR(__xludf.DUMMYFUNCTION("""COMPUTED_VALUE"""),"SS0017") -> SS0017 | B18: {=_xludf.XLOOKUP(A18, 도서_정보[ID], 도서_정보[도서명], "")} -> #NAME? | C18: {=_xludf.XLOOKUP(A18, 도서_정보[ID], 도서_정보[작업 페이지], "")} -> #NAME? | D18: FALSE | E18: FALSE | F18: FALSE | G18: FALSE | H18: FALSE | I18: FALSE | J18: FALSE | K18: FALSE | L18: FALSE | M18: FALSE | N18: {=_xludf.XLOOKUP(A18,'3. 도서별 작업 현황'!A:A,'3. 도서별 작업 현황'!Z:Z,"")} -> #NAME?
A19: =IFERROR(__xludf.DUMMYFUNCTION("""COMPUTED_VALUE"""),"SS0018") -> SS0018 | B19: {=_xludf.XLOOKUP(A19, 도서_정보[ID], 도서_정보[도서명], "")} -> #NAME? | C19: {=_xludf.XLOOKUP(A19, 도서_정보[ID], 도서_정보[작업 페이지], "")} -> #NAME? | D19: FALSE | E19: FALSE | F19: FALSE | G19: FALSE | H19: FALSE | I19: FALSE | J19: FALSE | K19: FALSE | L19: FALSE | M19: FALSE | N19: {=_xludf.XLOOKUP(A19,'3. 도서별 작업 현황'!A:A,'3. 도서별 작업 현황'!Z:Z,"")} -> #NAME?
A20: =IFERROR(__xludf.DUMMYFUNCTION("""COMPUTED_VALUE"""),"SS0019") -> SS0019 | B20: {=_xludf.XLOOKUP(A20, 도서_정보[ID], 도서_정보[도서명], "")} -> #NAME? | C20: {=_xludf.XLOOKUP(A20, 도서_정보[ID], 도서_정보[작업 페이지], "")} -> #NAME? | D20: FALSE | E20: FALSE | F20: FALSE | G20: FALSE | H20: FALSE | I20: FALSE | J20: FALSE | K20: FALSE | L20: FALSE | M20: FALSE | N20: {=_xludf.XLOOKUP(A20,'3. 도서별 작업 현황'!A:A,'3. 도서별 작업 현황'!Z:Z,"")} -> #NAME?
A21: =IFERROR(__xludf.DUMMYFUNCTION("""COMPUTED_VALUE"""),"SS0020") -> SS0020 | B21: {=_xludf.XLOOKUP(A21, 도서_정보[ID], 도서_정보[도서명], "")} -> #NAME? | C21: {=_xludf.XLOOKUP(A21, 도서_정보[ID], 도서_정보[작업 페이지], "")} -> #NAME? | D21: FALSE | E21: FALSE | F21: FALSE | G21: FALSE | H21: FALSE | I21: FALSE | J21: FALSE | K21: FALSE | L21: FALSE | M21: FALSE | N21: {=_xludf.XLOOKUP(A21,'3. 도서별 작업 현황'!A:A,'3. 도서별 작업 현황'!Z:Z,"")} -> #NAME?
A22: =IFERROR(__xludf.DUMMYFUNCTION("""COMPUTED_VALUE"""),"SS0021") -> SS0021 | B22: {=_xludf.XLOOKUP(A22, 도서_정보[ID], 도서_정보[도서명], "")} -> #NAME? | C22: {=_xludf.XLOOKUP(A22, 도서_정보[ID], 도서_정보[작업 페이지], "")} -> #NAME? | D22: FALSE | E22: FALSE | F22: FALSE | G22: FALSE | H22: FALSE | I22: FALSE | J22: FALSE | K22: FALSE | L22: FALSE | M22: FALSE | N22: {=_xludf.XLOOKUP(A22,'3. 도서별 작업 현황'!A:A,'3. 도서별 작업 현황'!Z:Z,"")} -> #NAME?
A23: =IFERROR(__xludf.DUMMYFUNCTION("""COMPUTED_VALUE"""),"SS0022") -> SS0022 | B23: {=_xludf.XLOOKUP(A23, 도서_정보[ID], 도서_정보[도서명], "")} -> #NAME? | C23: {=_xludf.XLOOKUP(A23, 도서_정보[ID], 도서_정보[작업 페이지], "")} -> #NAME? | D23: FALSE | E23: FALSE | F23: FALSE | G23: FALSE | H23: FALSE | I23: FALSE | J23: FALSE | K23: FALSE | L23: FALSE | M23: FALSE | N23: {=_xludf.XLOOKUP(A23,'3. 도서별 작업 현황'!A:A,'3. 도서별 작업 현황'!Z:Z,"")} -> #NAME?
A24: =IFERROR(__xludf.DUMMYFUNCTION("""COMPUTED_VALUE"""),"SS0023") -> SS0023 | B24: {=_xludf.XLOOKUP(A24, 도서_정보[ID], 도서_정보[도서명], "")} -> #NAME? | C24: {=_xludf.XLOOKUP(A24, 도서_정보[ID], 도서_정보[작업 페이지], "")} -> #NAME? | D24: FALSE | E24: FALSE | F24: FALSE | G24: FALSE | H24: FALSE | I24: FALSE | J24: FALSE | K24: FALSE | L24: FALSE | M24: FALSE | N24: {=_xludf.XLOOKUP(A24,'3. 도서별 작업 현황'!A:A,'3. 도서별 작업 현황'!Z:Z,"")} -> #NAME?
A25: =IFERROR(__xludf.DUMMYFUNCTION("""COMPUTED_VALUE"""),"SS0024") -> SS0024 | B25: {=_xludf.XLOOKUP(A25, 도서_정보[ID], 도서_정보[도서명], "")} -> #NAME? | C25: {=_xludf.XLOOKUP(A25, 도서_정보[ID], 도서_정보[작업 페이지], "")} -> #NAME? | D25: FALSE | E25: FALSE | F25: FALSE | G25: FALSE | H25: FALSE | I25: FALSE | J25: FALSE | K25: FALSE | L25: FALSE | M25: FALSE | N25: {=_xludf.XLOOKUP(A25,'3. 도서별 작업 현황'!A:A,'3. 도서별 작업 현황'!Z:Z,"")} -> #NAME?
A26: =IFERROR(__xludf.DUMMYFUNCTION("""COMPUTED_VALUE"""),"SS0025") -> SS0025 | B26: {=_xludf.XLOOKUP(A26, 도서_정보[ID], 도서_정보[도서명], "")} -> #NAME? | C26: {=_xludf.XLOOKUP(A26, 도서_정보[ID], 도서_정보[작업 페이지], "")} -> #NAME? | D26: FALSE | E26: FALSE | F26: FALSE | G26: FALSE | H26: FALSE | I26: FALSE | J26: FALSE | K26: FALSE | L26: FALSE | M26: FALSE | N26: {=_xludf.XLOOKUP(A26,'3. 도서별 작업 현황'!A:A,'3. 도서별 작업 현황'!Z:Z,"")} -> #NAME?
A27: =IFERROR(__xludf.DUMMYFUNCTION("""COMPUTED_VALUE"""),"SS0026") -> SS0026 | B27: {=_xludf.XLOOKUP(A27, 도서_정보[ID], 도서_정보[도서명], "")} -> #NAME? | C27: {=_xludf.XLOOKUP(A27, 도서_정보[ID], 도서_정보[작업 페이지], "")} -> #NAME? | D27: FALSE | E27: FALSE | F27: FALSE | G27: FALSE | H27: FALSE | I27: FALSE | J27: FALSE | K27: FALSE | L27: FALSE | M27: FALSE | N27: {=_xludf.XLOOKUP(A27,'3. 도서별 작업 현황'!A:A,'3. 도서별 작업 현황'!Z:Z,"")} -> #NAME?
A28: =IFERROR(__xludf.DUMMYFUNCTION("""COMPUTED_VALUE"""),"SS0027") -> SS0027 | B28: {=_xludf.XLOOKUP(A28, 도서_정보[ID], 도서_정보[도서명], "")} -> #NAME? | C28: {=_xludf.XLOOKUP(A28, 도서_정보[ID], 도서_정보[작업 페이지], "")} -> #NAME? | D28: FALSE | E28: FALSE | F28: FALSE | G28: FALSE | H28: FALSE | I28: FALSE | J28: FALSE | K28: FALSE | L28: FALSE | M28: FALSE | N28: {=_xludf.XLOOKUP(A28,'3. 도서별 작업 현황'!A:A,'3. 도서별 작업 현황'!Z:Z,"")} -> #NAME?
A29: =IFERROR(__xludf.DUMMYFUNCTION("""COMPUTED_VALUE"""),"SS0028") -> SS0028 | B29: {=_xludf.XLOOKUP(A29, 도서_정보[ID], 도서_정보[도서명], "")} -> #NAME? | C29: {=_xludf.XLOOKUP(A29, 도서_정보[ID], 도서_정보[작업 페이지], "")} -> #NAME? | D29: FALSE | E29: FALSE | F29: FALSE | G29: FALSE | H29: FALSE | I29: FALSE | J29: FALSE | K29: FALSE | L29: FALSE | M29: FALSE | N29: {=_xludf.XLOOKUP(A29,'3. 도서별 작업 현황'!A:A,'3. 도서별 작업 현황'!Z:Z,"")} -> #NAME?
A30: =IFERROR(__xludf.DUMMYFUNCTION("""COMPUTED_VALUE"""),"SS0029") -> SS0029 | B30: {=_xludf.XLOOKUP(A30, 도서_정보[ID], 도서_정보[도서명], "")} -> #NAME? | C30: {=_xludf.XLOOKUP(A30, 도서_정보[ID], 도서_정보[작업 페이지], "")} -> #NAME? | D30: FALSE | E30: FALSE | F30: FALSE | G30: FALSE | H30: FALSE | I30: FALSE | J30: FALSE | K30: FALSE | L30: FALSE | M30: FALSE | N30: {=_xludf.XLOOKUP(A30,'3. 도서별 작업 현황'!A:A,'3. 도서별 작업 현황'!Z:Z,"")} -> #NAME?
A31: =IFERROR(__xludf.DUMMYFUNCTION("""COMPUTED_VALUE"""),"SS0030") -> SS0030 | B31: {=_xludf.XLOOKUP(A31, 도서_정보[ID], 도서_정보[도서명], "")} -> #NAME? | C31: {=_xludf.XLOOKUP(A31, 도서_정보[ID], 도서_정보[작업 페이지], "")} -> #NAME? | D31: FALSE | E31: FALSE | F31: FALSE | G31: FALSE | H31: FALSE | I31: FALSE | J31: FALSE | K31: FALSE | L31: FALSE | M31: FALSE | N31: {=_xludf.XLOOKUP(A31,'3. 도서별 작업 현황'!A:A,'3. 도서별 작업 현황'!Z:Z,"")} -> #NAME?
A32: =IFERROR(__xludf.DUMMYFUNCTION("""COMPUTED_VALUE"""),"SS0031") -> SS0031 | B32: {=_xludf.XLOOKUP(A32, 도서_정보[ID], 도서_정보[도서명], "")} -> #NAME? | C32: {=_xludf.XLOOKUP(A32, 도서_정보[ID], 도서_정보[작업 페이지], "")} -> #NAME? | D32: FALSE | E32: FALSE | F32: FALSE | G32: FALSE | H32: FALSE | I32: FALSE | J32: FALSE | K32: FALSE | L32: FALSE | M32: FALSE | N32: {=_xludf.XLOOKUP(A32,'3. 도서별 작업 현황'!A:A,'3. 도서별 작업 현황'!Z:Z,"")} -> #NAME?
A33: =IFERROR(__xludf.DUMMYFUNCTION("""COMPUTED_VALUE"""),"SS0032") -> SS0032 | B33: {=_xludf.XLOOKUP(A33, 도서_정보[ID], 도서_정보[도서명], "")} -> #NAME? | C33: {=_xludf.XLOOKUP(A33, 도서_정보[ID], 도서_정보[작업 페이지], "")} -> #NAME? | D33: FALSE | E33: FALSE | F33: FALSE | G33: FALSE | H33: FALSE | I33: FALSE | J33: FALSE | K33: FALSE | L33: FALSE | M33: FALSE | N33: {=_xludf.XLOOKUP(A33,'3. 도서별 작업 현황'!A:A,'3. 도서별 작업 현황'!Z:Z,"")} -> #NAME?
A34: =IFERROR(__xludf.DUMMYFUNCTION("""COMPUTED_VALUE"""),"SS0033") -> SS0033 | B34: {=_xludf.XLOOKUP(A34, 도서_정보[ID], 도서_정보[도서명], "")} -> #NAME? | C34: {=_xludf.XLOOKUP(A34, 도서_정보[ID], 도서_정보[작업 페이지], "")} -> #NAME? | D34: FALSE | E34: FALSE | F34: FALSE | G34: FALSE | H34: FALSE | I34: FALSE | J34: FALSE | K34: FALSE | L34: FALSE | M34: FALSE | N34: {=_xludf.XLOOKUP(A34,'3. 도서별 작업 현황'!A:A,'3. 도서별 작업 현황'!Z:Z,"")} -> #NAME?
A35: =IFERROR(__xludf.DUMMYFUNCTION("""COMPUTED_VALUE"""),"SS0034") -> SS0034 | B35: {=_xludf.XLOOKUP(A35, 도서_정보[ID], 도서_정보[도서명], "")} -> #NAME? | C35: {=_xludf.XLOOKUP(A35, 도서_정보[ID], 도서_정보[작업 페이지], "")} -> #NAME? | D35: FALSE | E35: FALSE | F35: FALSE | G35: FALSE | H35: FALSE | I35: FALSE | J35: FALSE | K35: FALSE | L35: FALSE | M35: FALSE | N35: {=_xludf.XLOOKUP(A35,'3. 도서별 작업 현황'!A:A,'3. 도서별 작업 현황'!Z:Z,"")} -> #NAME?
A36: =IFERROR(__xludf.DUMMYFUNCTION("""COMPUTED_VALUE"""),"SS0035") -> SS0035 | B36: {=_xludf.XLOOKUP(A36, 도서_정보[ID], 도서_정보[도서명], "")} -> #NAME? | C36: {=_xludf.XLOOKUP(A36, 도서_정보[ID], 도서_정보[작업 페이지], "")} -> #NAME? | D36: FALSE | E36: FALSE | F36: FALSE | G36: FALSE | H36: FALSE | I36: FALSE | J36: FALSE | K36: FALSE | L36: FALSE | M36: FALSE | N36: {=_xludf.XLOOKUP(A36,'3. 도서별 작업 현황'!A:A,'3. 도서별 작업 현황'!Z:Z,"")} -> #NAME?
A37: =IFERROR(__xludf.DUMMYFUNCTION("""COMPUTED_VALUE"""),"SS0036") -> SS0036 | B37: {=_xludf.XLOOKUP(A37, 도서_정보[ID], 도서_정보[도서명], "")} -> #NAME? | C37: {=_xludf.XLOOKUP(A37, 도서_정보[ID], 도서_정보[작업 페이지], "")} -> #NAME? | D37: FALSE | E37: FALSE | F37: FALSE | G37: FALSE | H37: FALSE | I37: FALSE | J37: FALSE | K37: FALSE | L37: FALSE | M37: FALSE | N37: {=_xludf.XLOOKUP(A37,'3. 도서별 작업 현황'!A:A,'3. 도서별 작업 현황'!Z:Z,"")} -> #NAME?
A38: =IFERROR(__xludf.DUMMYFUNCTION("""COMPUTED_VALUE"""),"SS0037") -> SS0037 | B38: {=_xludf.XLOOKUP(A38, 도서_정보[ID], 도서_정보[도서명], "")} -> #NAME? | C38: {=_xludf.XLOOKUP(A38, 도서_정보[ID], 도서_정보[작업 페이지], "")} -> #NAME? | D38: FALSE | E38: FALSE | F38: FALSE | G38: FALSE | H38: FALSE | I38: FALSE | J38: FALSE | K38: FALSE | L38: FALSE | M38: FALSE | N38: {=_xludf.XLOOKUP(A38,'3. 도서별 작업 현황'!A:A,'3. 도서별 작업 현황'!Z:Z,"")} -> #NAME?
A39: =IFERROR(__xludf.DUMMYFUNCTION("""COMPUTED_VALUE"""),"SS0038") -> SS0038 | B39: {=_xludf.XLOOKUP(A39, 도서_정보[ID], 도서_정보[도서명], "")} -> #NAME? | C39: {=_xludf.XLOOKUP(A39, 도서_정보[ID], 도서_정보[작업 페이지], "")} -> #NAME? | D39: FALSE | E39: FALSE | F39: FALSE | G39: FALSE | H39: FALSE | I39: FALSE | J39: FALSE | K39: FALSE | L39: FALSE | M39: FALSE | N39: {=_xludf.XLOOKUP(A39,'3. 도서별 작업 현황'!A:A,'3. 도서별 작업 현황'!Z:Z,"")} -> #NAME?
A40: =IFERROR(__xludf.DUMMYFUNCTION("""COMPUTED_VALUE"""),"SS0039") -> SS0039 | B40: {=_xludf.XLOOKUP(A40, 도서_정보[ID], 도서_정보[도서명], "")} -> #NAME? | C40: {=_xludf.XLOOKUP(A40, 도서_정보[ID], 도서_정보[작업 페이지], "")} -> #NAME? | D40: FALSE | E40: FALSE | F40: FALSE | G40: FALSE | H40: FALSE | I40: FALSE | J40: FALSE | K40: FALSE | L40: FALSE | M40: FALSE | N40: {=_xludf.XLOOKUP(A40,'3. 도서별 작업 현황'!A:A,'3. 도서별 작업 현황'!Z:Z,"")} -> #NAME?
...

Sheet PoC
B2: 2026년 최저 시급 | D2: 10320
B4: BBOX 작업 : DLA 보정 OCR 작업 : OCR, 태그 작업 | J4: LaTeX 작업 : 추출된 LaTeX 수식 수정 HTML 작업 : 추출된 HTML 표 수정
B7: BBOX&OCR | J7: HTML_표 / LaTeX_수식
B8: 난이도 | C8: 도서ID | D8: 작업자 | E8: 페이지 수 | F8: 작업 시간(s) | G8: 단가 | J8: 난이도 | K8: 도서ID | L8: 작업자 | M8: 페이지 수 | N8: 작업 시간(s) | O8: 단가
B9: SS | E9: 10 | F9: 200 | G9: =$D$2/3600/(F9/E9) -> 0.14333333 | J9: SS | M9: 10 | N9: 200 | O9: =$D$2/3600/(N9/M9) -> 0.14333333
E10: 12 | F10: 200 | G10: =$D$2/3600/(F10/E10) -> 0.172 | O10: =$D$2/3600/(N10/M10) -> #DIV/0!
E11: 9 | F11: 200 | G11: =$D$2/3600/(F11/E11) -> 0.129 | H11: =IFERROR(__xludf.DUMMYFUNCTION("AVERAGE(FILTER(G9:G11,ISNUMBER(G9:G11)))"),56.2716049382716) -> 56.271605 | O11: =$D$2/3600/(N11/M11) -> #DIV/0!
G12: =$D$2/3600/(F12/E12) -> #DIV/0! | O12: =$D$2/3600/(N12/M12) -> #DIV/0! | P12: =IFERROR(__xludf.DUMMYFUNCTION("AVERAGE(FILTER(O9:O12,ISNUMBER(O9:O12)))"),57.3333333333333) -> 57.333333
G13: =$D$2/3600/(F13/E13) -> #DIV/0!
G14: =$D$2/3600/(F14/E14) -> #DIV/0! | H14: =IFERROR(__xludf.DUMMYFUNCTION("AVERAGE(FILTER(G12:G14,ISNUMBER(G12:G14)))"),"#N/A") -> #N/A
G15: =$D$2/3600/(F15/E15) -> #DIV/0!
G16: =$D$2/3600/(F16/E16) -> #DIV/0!
G17: =$D$2/3600/(F17/E17) -> #DIV/0! | H17: =IFERROR(__xludf.DUMMYFUNCTION("AVERAGE(FILTER(G15:G17,ISNUMBER(G15:G17)))"),"#N/A") -> #N/A
G18: =$D$2/3600/(F18/E18) -> #DIV/0!
G19: =$D$2/3600/(F19/E19) -> #DIV/0!
G20: =$D$2/3600/(F20/E20) -> #DIV/0! | H20: =IFERROR(__xludf.DUMMYFUNCTION("AVERAGE(FILTER(G18:G20,ISNUMBER(G18:G20)))"),"#N/A") -> #N/A
G21: =$D$2/3600/(F21/E21) -> #DIV/0!
G22: =$D$2/3600/(F22/E22) -> #DIV/0!
G23: =$D$2/3600/(F23/E23) -> #DIV/0! | H23: =IFERROR(__xludf.DUMMYFUNCTION("AVERAGE(FILTER(G21:G23,ISNUMBER(G21:G23)))"),"#N/A") -> #N/A

Sheet 작업자 정산관리
A2: 이름 | B2: 코드네임 | C2: 작업명 | D2: 작업량

Sheet WER 로그
A1: ID | B1: 도서명 | C1: WER 검수자 | D1: 작업 페이지 | E1: 검수 페이지 | F1: 검수 페이지 비율 | G1: 검사 어절 수 | H1: 오류 어절 수 | I1: 1-WER | J1: 수정 후 1-WER
A2: ='3. 도서별 작업 현황'!A2 -> SS0001 | B2: {=_xludf.XLOOKUP(A2,'2. 도서 정보'!A:A,'2. 도서 정보'!B:B,"")} -> #NAME? | C2: {=_xludf.XLOOKUP(A2,'3. 도서별 작업 현황'!A:A,'3. 도서별 작업 현황'!W:W,"")} -> #NAME? | D2: {=_xludf.XLOOKUP(A2,'2. 도서 정보'!A:A,'2. 도서 정보'!N:N,"")} -> #NAME?
A3: ='3. 도서별 작업 현황'!A3 -> SS0002 | B3: {=_xludf.XLOOKUP(A3,'2. 도서 정보'!A:A,'2. 도서 정보'!B:B,"")} -> #NAME? | D3: {=_xludf.XLOOKUP(A3,'2. 도서 정보'!A:A,'2. 도서 정보'!N:N,"")} -> #NAME?
A4: ='3. 도서별 작업 현황'!A4 -> SS0003 | B4: {=_xludf.XLOOKUP(A4,'2. 도서 정보'!A:A,'2. 도서 정보'!B:B,"")} -> #NAME? | D4: {=_xludf.XLOOKUP(A4,'2. 도서 정보'!A:A,'2. 도서 정보'!N:N,"")} -> #NAME?
A5: ='3. 도서별 작업 현황'!A5 -> SS0004 | B5: {=_xludf.XLOOKUP(A5,'2. 도서 정보'!A:A,'2. 도서 정보'!B:B,"")} -> #NAME? | D5: {=_xludf.XLOOKUP(A5,'2. 도서 정보'!A:A,'2. 도서 정보'!N:N,"")} -> #NAME?
A6: ='3. 도서별 작업 현황'!A6 -> SS0005 | B6: {=_xludf.XLOOKUP(A6,'2. 도서 정보'!A:A,'2. 도서 정보'!B:B,"")} -> #NAME? | D6: {=_xludf.XLOOKUP(A6,'2. 도서 정보'!A:A,'2. 도서 정보'!N:N,"")} -> #NAME?
A7: ='3. 도서별 작업 현황'!A7 -> SS0006 | B7: {=_xludf.XLOOKUP(A7,'2. 도서 정보'!A:A,'2. 도서 정보'!B:B,"")} -> #NAME? | D7: {=_xludf.XLOOKUP(A7,'2. 도서 정보'!A:A,'2. 도서 정보'!N:N,"")} -> #NAME?
A8: ='3. 도서별 작업 현황'!A8 -> SS0007 | B8: {=_xludf.XLOOKUP(A8,'2. 도서 정보'!A:A,'2. 도서 정보'!B:B,"")} -> #NAME? | D8: {=_xludf.XLOOKUP(A8,'2. 도서 정보'!A:A,'2. 도서 정보'!N:N,"")} -> #NAME?
A9: ='3. 도서별 작업 현황'!A9 -> SS0008 | B9: {=_xludf.XLOOKUP(A9,'2. 도서 정보'!A:A,'2. 도서 정보'!B:B,"")} -> #NAME? | D9: {=_xludf.XLOOKUP(A9,'2. 도서 정보'!A:A,'2. 도서 정보'!N:N,"")} -> #NAME?
A10: ='3. 도서별 작업 현황'!A10 -> SS0009 | B10: {=_xludf.XLOOKUP(A10,'2. 도서 정보'!A:A,'2. 도서 정보'!B:B,"")} -> #NAME? | D10: {=_xludf.XLOOKUP(A10,'2. 도서 정보'!A:A,'2. 도서 정보'!N:N,"")} -> #NAME?
A11: ='3. 도서별 작업 현황'!A11 -> SS0010 | B11: {=_xludf.XLOOKUP(A11,'2. 도서 정보'!A:A,'2. 도서 정보'!B:B,"")} -> #NAME? | D11: {=_xludf.XLOOKUP(A11,'2. 도서 정보'!A:A,'2. 도서 정보'!N:N,"")} -> #NAME?
A12: ='3. 도서별 작업 현황'!A12 -> SS0011 | B12: {=_xludf.XLOOKUP(A12,'2. 도서 정보'!A:A,'2. 도서 정보'!B:B,"")} -> #NAME? | D12: {=_xludf.XLOOKUP(A12,'2. 도서 정보'!A:A,'2. 도서 정보'!N:N,"")} -> #NAME?
A13: ='3. 도서별 작업 현황'!A13 -> SS0012 | B13: {=_xludf.XLOOKUP(A13,'2. 도서 정보'!A:A,'2. 도서 정보'!B:B,"")} -> #NAME? | D13: {=_xludf.XLOOKUP(A13,'2. 도서 정보'!A:A,'2. 도서 정보'!N:N,"")} -> #NAME?
A14: ='3. 도서별 작업 현황'!A14 -> SS0013 | B14: {=_xludf.XLOOKUP(A14,'2. 도서 정보'!A:A,'2. 도서 정보'!B:B,"")} -> #NAME? | D14: {=_xludf.XLOOKUP(A14,'2. 도서 정보'!A:A,'2. 도서 정보'!N:N,"")} -> #NAME?
A15: ='3. 도서별 작업 현황'!A15 -> SS0014 | B15: {=_xludf.XLOOKUP(A15,'2. 도서 정보'!A:A,'2. 도서 정보'!B:B,"")} -> #NAME? | D15: {=_xludf.XLOOKUP(A15,'2. 도서 정보'!A:A,'2. 도서 정보'!N:N,"")} -> #NAME?

Sheet 드롭다운 클래스
A1: 추출 방식 | B1: 난이도 | C1: 납품 차수 | D1: 검수자 | E1: 작업 상태
A2: fitz | B2: SS | C2: 샘플 납품 | D2: PM | E2: 분배X
A3: gemini | B3: A | C3: 최종 납품 | D3: DA1 | E3: 진행 중
A4: GPT | B4: B | D4: DA2 | E4: 작업 완료
A5: 내부 모델 | B5: C | E5: 검수 완료
